<robot
  name="rmc_simulation">
  <link
    name="base_link">
    <inertial>
      <origin
        xyz="0.0719191525595428 -0.529514025798947 0.258354886671981"
        rpy="0 0 0" />
      <mass
        value="5.21776221348033" />
      <inertia
        ixx="0.389997796058234"
        ixy="9.71316981309733E-06"
        ixz="-0.000223596199441625"
        iyy="0.310798205396144"
        iyz="-0.0567353943990997"
        izz="0.538173547982933" />
    </inertial>
    <visual>
      <origin
        xyz="0 0 0"
        rpy="0 0 0" />
      <geometry>
        <mesh
          filename="package://rmc_simulation/meshes/base_link.STL" />
      </geometry>
      <material
        name="">
        <color
          rgba="0.752941176470588 0.752941176470588 0.752941176470588 1" />
      </material>
    </visual>
    <collision>
      <origin
        xyz="0 0 0"
        rpy="0 0 0" />
      <geometry>
        <mesh
          filename="package://rmc_simulation/meshes/base_link.STL" />
      </geometry>
    </collision>
  </link>
  <link
    name="fr_wheel_link">
    <inertial>
      <origin
        xyz="-7.19149739758507E-12 -0.0707951640907282 -1.95886141474144E-07"
        rpy="0 0 0" />
      <mass
        value="0.687645998614542" />
      <inertia
        ixx="0.00410397321446005"
        ixy="1.94069035037664E-13"
        ixz="1.05933082875857E-14"
        iyy="0.00552463397717715"
        iyz="5.39169464241662E-09"
        izz="0.00410397301758295" />
    </inertial>
    <visual>
      <origin
        xyz="0 0 0"
        rpy="0 0 0" />
      <geometry>
        <mesh
          filename="package://rmc_simulation/meshes/fr_wheel_link.STL" />
      </geometry>
      <material
        name="">
        <color
          rgba="0.752941176470588 0.752941176470588 0.752941176470588 1" />
      </material>
    </visual>
    <collision>
      <origin
        xyz="0 0 0"
        rpy="0 0 0" />
      <geometry>
        <mesh
          filename="package://rmc_simulation/meshes/fr_wheel_link.STL" />
      </geometry>
    </collision>
  </link>
  <joint
    name="fr_wheel_joint"
    type="continuous">
    <origin
      xyz="0.322993191374717 -0.0779327659083641 0.0778552780598406"
      rpy="3.14159265358979 -1.56862653893506 -1.5707963267949" />
    <parent
      link="base_link" />
    <child
      link="fr_wheel_link" />
    <axis
      xyz="0 1 0" />
  </joint>
  <link
    name="mr_wheel_link">
    <inertial>
      <origin
        xyz="-7.30707161444855E-12 -0.0707951640913478 -1.95886142140278E-07"
        rpy="0 0 0" />
      <mass
        value="0.687645998625396" />
      <inertia
        ixx="0.00410397321447679"
        ixy="1.97149627284804E-13"
        ixz="1.06925102452693E-14"
        iyy="0.00552463397717739"
        iyz="5.39169467425826E-09"
        izz="0.00410397301759992" />
    </inertial>
    <visual>
      <origin
        xyz="0 0 0"
        rpy="0 0 0" />
      <geometry>
        <mesh
          filename="package://rmc_simulation/meshes/mr_wheel_link.STL" />
      </geometry>
      <material
        name="">
        <color
          rgba="0.752941176470588 0.752941176470588 0.752941176470588 1" />
      </material>
    </visual>
    <collision>
      <origin
        xyz="0 0 0"
        rpy="0 0 0" />
      <geometry>
        <mesh
          filename="package://rmc_simulation/meshes/mr_wheel_link.STL" />
      </geometry>
    </collision>
  </link>
  <joint
    name="mr_wheel_joint"
    type="continuous">
    <origin
      xyz="0.322993191374717 -0.433641505259442 0.0778067127306861"
      rpy="1.5707963267949 -1.5707963267949 0" />
    <parent
      link="base_link" />
    <child
      link="mr_wheel_link" />
    <axis
      xyz="0 1 0" />
  </joint>
  <link
    name="br_wheel_link">
    <inertial>
      <origin
        xyz="-2.56872301207522E-12 -0.0707920435844434 -1.95886293075098E-07"
        rpy="0 0 0" />
      <mass
        value="0.687645998094418" />
      <inertia
        ixx="0.00410397321363925"
        ixy="7.41448411831201E-14"
        ixz="7.32617091991905E-15"
        iyy="0.00552463397716753"
        iyz="5.39170125726693E-09"
        izz="0.00410397301675641" />
    </inertial>
    <visual>
      <origin
        xyz="0 0 0"
        rpy="0 0 0" />
      <geometry>
        <mesh
          filename="package://rmc_simulation/meshes/br_wheel_link.STL" />
      </geometry>
      <material
        name="">
        <color
          rgba="0.752941176470588 0.752941176470588 0.752941176470588 1" />
      </material>
    </visual>
    <collision>
      <origin
        xyz="0 0 0"
        rpy="0 0 0" />
      <geometry>
        <mesh
          filename="package://rmc_simulation/meshes/br_wheel_link.STL" />
      </geometry>
    </collision>
  </link>
  <joint
    name="br_wheel_joint"
    type="continuous">
    <origin
      xyz="0.323202134134549 -0.770124006916524 0.07664686034817"
      rpy="3.13028479554889 -1.11701573915485 -1.56063278319395" />
    <parent
      link="base_link" />
    <child
      link="br_wheel_link" />
    <axis
      xyz="0 1 0" />
  </joint>
  <link
    name="fl_wheel_link">
    <inertial>
      <origin
        xyz="-7.3069883477217E-12 -0.0707951640913485 -1.958861421264E-07"
        rpy="0 0 0" />
      <mass
        value="0.687645998625407" />
      <inertia
        ixx="0.00410397321447676"
        ixy="1.97154306294804E-13"
        ixz="1.06921443270361E-14"
        iyy="0.00552463397717734"
        iyz="5.39169467501382E-09"
        izz="0.0041039730175999" />
    </inertial>
    <visual>
      <origin
        xyz="0 0 0"
        rpy="0 0 0" />
      <geometry>
        <mesh
          filename="package://rmc_simulation/meshes/fl_wheel_link.STL" />
      </geometry>
      <material
        name="">
        <color
          rgba="0.752941176470588 0.752941176470588 0.752941176470588 1" />
      </material>
    </visual>
    <collision>
      <origin
        xyz="0 0 0"
        rpy="0 0 0" />
      <geometry>
        <mesh
          filename="package://rmc_simulation/meshes/fl_wheel_link.STL" />
      </geometry>
    </collision>
  </link>
  <joint
    name="fl_wheel_joint"
    type="continuous">
    <origin
      xyz="-0.179281808625283 -0.0779740069165238 0.0778309873766015"
      rpy="1.5707963267949 1.5707963267949 0" />
    <parent
      link="base_link" />
    <child
      link="fl_wheel_link" />
    <axis
      xyz="0 -1 0" />
  </joint>
  <link
    name="ml_wheel_link">
    <inertial>
      <origin
        xyz="-7.30701610329731E-12 -0.0707951640913486 -1.95886142084767E-07"
        rpy="0 0 0" />
      <mass
        value="0.687645998625407" />
      <inertia
        ixx="0.00410397321447676"
        ixy="1.9715426479019E-13"
        ixz="1.06918326189115E-14"
        iyy="0.00552463397717734"
        iyz="5.3916946743328E-09"
        izz="0.0041039730175999" />
    </inertial>
    <visual>
      <origin
        xyz="0 0 0"
        rpy="0 0 0" />
      <geometry>
        <mesh
          filename="package://rmc_simulation/meshes/ml_wheel_link.STL" />
      </geometry>
      <material
        name="">
        <color
          rgba="0.752941176470588 0.752941176470588 0.752941176470588 1" />
      </material>
    </visual>
    <collision>
      <origin
        xyz="0 0 0"
        rpy="0 0 0" />
      <geometry>
        <mesh
          filename="package://rmc_simulation/meshes/ml_wheel_link.STL" />
      </geometry>
    </collision>
  </link>
  <joint
    name="ml_wheel_joint"
    type="continuous">
    <origin
      xyz="-0.179281808625283 -0.433574006916524 0.0778309873766015"
      rpy="1.5707963267949 1.5707963267949 0" />
    <parent
      link="base_link" />
    <child
      link="ml_wheel_link" />
    <axis
      xyz="0 -1 0" />
  </joint>
  <link
    name="bl_wheel_link">
    <inertial>
      <origin
        xyz="-7.71939456800652E-12 -0.0707920436121963 -1.95886686760183E-07"
        rpy="0 0 0" />
      <mass
        value="0.687645998581504" />
      <inertia
        ixx="0.00410397321438875"
        ixy="2.09611323388542E-13"
        ixz="1.05896089746637E-14"
        iyy="0.00552463397717644"
        iyz="5.39171353515359E-09"
        izz="0.00410397301751382" />
    </inertial>
    <visual>
      <origin
        xyz="0 0 0"
        rpy="0 0 0" />
      <geometry>
        <mesh
          filename="package://rmc_simulation/meshes/bl_wheel_link.STL" />
      </geometry>
      <material
        name="">
        <color
          rgba="0.752941176470588 0.752941176470588 0.752941176470588 1" />
      </material>
    </visual>
    <collision>
      <origin
        xyz="0 0 0"
        rpy="0 0 0" />
      <geometry>
        <mesh
          filename="package://rmc_simulation/meshes/bl_wheel_link.STL" />
      </geometry>
    </collision>
  </link>
  <joint
    name="bl_wheel_joint"
    type="continuous">
    <origin
      xyz="-0.180876313928926 -0.770124006916524 0.0791455484611853"
      rpy="-1.57079632679488 1.56583942443656 -3.14159265358978" />
    <parent
      link="base_link" />
    <child
      link="bl_wheel_link" />
    <axis
      xyz="0 -1 0" />
  </joint>
</robot>